[2024-05-20T10:02:40.087+0000] {local_task_job_runner.py:120} INFO - ::group::Pre task execution logs
[2024-05-20T10:02:40.099+0000] {taskinstance.py:2076} INFO - Dependencies all met for dep_context=non-requeueable deps ti=<TaskInstance: domain_url_analysis.fetch_domains manual__2024-05-20T09:58:37.278208+00:00 [queued]>
[2024-05-20T10:02:40.102+0000] {taskinstance.py:2076} INFO - Dependencies all met for dep_context=requeueable deps ti=<TaskInstance: domain_url_analysis.fetch_domains manual__2024-05-20T09:58:37.278208+00:00 [queued]>
[2024-05-20T10:02:40.102+0000] {taskinstance.py:2306} INFO - Starting attempt 1 of 2
[2024-05-20T10:02:40.106+0000] {taskinstance.py:2330} INFO - Executing <Task(PythonOperator): fetch_domains> on 2024-05-20 09:58:37.278208+00:00
[2024-05-20T10:02:40.108+0000] {logging_mixin.py:188} WARNING - /home/***/.local/lib/python3.12/site-packages/***/task/task_runner/standard_task_runner.py:61 DeprecationWarning: This process (pid=342) is multi-threaded, use of fork() may lead to deadlocks in the child.
[2024-05-20T10:02:40.108+0000] {standard_task_runner.py:63} INFO - Started process 343 to run task
[2024-05-20T10:02:40.108+0000] {standard_task_runner.py:90} INFO - Running: ['***', 'tasks', 'run', 'domain_url_analysis', 'fetch_domains', 'manual__2024-05-20T09:58:37.278208+00:00', '--job-id', '262', '--raw', '--subdir', 'DAGS_FOLDER/analysis_dag.py', '--cfg-path', '/tmp/tmp_tl44jzi']
[2024-05-20T10:02:40.109+0000] {standard_task_runner.py:91} INFO - Job 262: Subtask fetch_domains
[2024-05-20T10:02:40.115+0000] {logging_mixin.py:188} WARNING - /home/***/.local/lib/python3.12/site-packages/***/settings.py:195 DeprecationWarning: The sql_alchemy_conn option in [core] has been moved to the sql_alchemy_conn option in [database] - the old setting has been used, but please update your config.
[2024-05-20T10:02:40.127+0000] {task_command.py:426} INFO - Running <TaskInstance: domain_url_analysis.fetch_domains manual__2024-05-20T09:58:37.278208+00:00 [running]> on host 99ec2e50f1b5
[2024-05-20T10:02:40.155+0000] {taskinstance.py:2648} INFO - Exporting env vars: AIRFLOW_CTX_DAG_OWNER='***' AIRFLOW_CTX_DAG_ID='domain_url_analysis' AIRFLOW_CTX_TASK_ID='fetch_domains' AIRFLOW_CTX_EXECUTION_DATE='2024-05-20T09:58:37.278208+00:00' AIRFLOW_CTX_TRY_NUMBER='1' AIRFLOW_CTX_DAG_RUN_ID='manual__2024-05-20T09:58:37.278208+00:00'
[2024-05-20T10:02:40.155+0000] {taskinstance.py:430} INFO - ::endgroup::
[2024-05-20T10:02:40.163+0000] {taskinstance.py:441} INFO - ::group::Post task execution logs
[2024-05-20T10:02:40.167+0000] {taskinstance.py:2905} ERROR - Task failed with exception
Traceback (most recent call last):
  File "/home/airflow/.local/lib/python3.12/site-packages/airflow/models/taskinstance.py", line 465, in _execute_task
    result = _execute_callable(context=context, **execute_callable_kwargs)
             ^^^^^^^^^^^^^^^^^^^^^^^^^^^^^^^^^^^^^^^^^^^^^^^^^^^^^^^^^^^^^
  File "/home/airflow/.local/lib/python3.12/site-packages/airflow/models/taskinstance.py", line 432, in _execute_callable
    return execute_callable(context=context, **execute_callable_kwargs)
           ^^^^^^^^^^^^^^^^^^^^^^^^^^^^^^^^^^^^^^^^^^^^^^^^^^^^^^^^^^^^
  File "/home/airflow/.local/lib/python3.12/site-packages/airflow/models/baseoperator.py", line 400, in wrapper
    return func(self, *args, **kwargs)
           ^^^^^^^^^^^^^^^^^^^^^^^^^^^
  File "/home/airflow/.local/lib/python3.12/site-packages/airflow/operators/python.py", line 235, in execute
    return_value = self.execute_callable()
                   ^^^^^^^^^^^^^^^^^^^^^^^
  File "/home/airflow/.local/lib/python3.12/site-packages/airflow/operators/python.py", line 252, in execute_callable
    return self.python_callable(*self.op_args, **self.op_kwargs)
           ^^^^^^^^^^^^^^^^^^^^^^^^^^^^^^^^^^^^^^^^^^^^^^^^^^^^^
  File "/opt/airflow/dags/analysis_dag.py", line 32, in fetch_domains
    conn = pg_hook.get_conn()
           ^^^^^^^^^^^^^^^^^^
  File "/home/airflow/.local/lib/python3.12/site-packages/airflow/providers/postgres/hooks/postgres.py", line 131, in get_conn
    conn = deepcopy(self.connection or self.get_connection(conn_id))
                                       ^^^^^^^^^^^^^^^^^^^^^^^^^^^^
  File "/home/airflow/.local/lib/python3.12/site-packages/airflow/hooks/base.py", line 83, in get_connection
    conn = Connection.get_connection_from_secrets(conn_id)
           ^^^^^^^^^^^^^^^^^^^^^^^^^^^^^^^^^^^^^^^^^^^^^^^
  File "/home/airflow/.local/lib/python3.12/site-packages/airflow/models/connection.py", line 519, in get_connection_from_secrets
    raise AirflowNotFoundException(f"The conn_id `{conn_id}` isn't defined")
airflow.exceptions.AirflowNotFoundException: The conn_id `***` isn't defined
[2024-05-20T10:02:40.169+0000] {taskinstance.py:1206} INFO - Marking task as UP_FOR_RETRY. dag_id=domain_url_analysis, task_id=fetch_domains, run_id=manual__2024-05-20T09:58:37.278208+00:00, execution_date=20240520T095837, start_date=20240520T100240, end_date=20240520T100240
[2024-05-20T10:02:40.172+0000] {standard_task_runner.py:110} ERROR - Failed to execute job 262 for task fetch_domains (The conn_id `***` isn't defined; 343)
[2024-05-20T10:02:40.210+0000] {local_task_job_runner.py:240} INFO - Task exited with return code 1
[2024-05-20T10:02:40.219+0000] {taskinstance.py:3498} INFO - 0 downstream tasks scheduled from follow-on schedule check
[2024-05-20T10:02:40.219+0000] {local_task_job_runner.py:222} INFO - ::endgroup::
