[2024-06-01T03:18:16.860+0000] {local_task_job_runner.py:120} INFO - ::group::Pre task execution logs
[2024-06-01T03:18:16.873+0000] {taskinstance.py:2076} INFO - Dependencies all met for dep_context=non-requeueable deps ti=<TaskInstance: soc_domain_analysis.domain_analysis manual__2024-06-01T03:18:16.454131+00:00 [queued]>
[2024-06-01T03:18:16.876+0000] {taskinstance.py:2076} INFO - Dependencies all met for dep_context=requeueable deps ti=<TaskInstance: soc_domain_analysis.domain_analysis manual__2024-06-01T03:18:16.454131+00:00 [queued]>
[2024-06-01T03:18:16.877+0000] {taskinstance.py:2306} INFO - Starting attempt 1 of 3
[2024-06-01T03:18:16.881+0000] {taskinstance.py:2330} INFO - Executing <Task(PythonOperator): domain_analysis> on 2024-06-01 03:18:16.454131+00:00
[2024-06-01T03:18:16.883+0000] {logging_mixin.py:188} WARNING - /home/***/.local/lib/python3.12/site-packages/***/task/task_runner/standard_task_runner.py:61 DeprecationWarning: This process (pid=430) is multi-threaded, use of fork() may lead to deadlocks in the child.
[2024-06-01T03:18:16.884+0000] {standard_task_runner.py:63} INFO - Started process 431 to run task
[2024-06-01T03:18:16.883+0000] {standard_task_runner.py:90} INFO - Running: ['***', 'tasks', 'run', 'soc_domain_analysis', 'domain_analysis', 'manual__2024-06-01T03:18:16.454131+00:00', '--job-id', '3673', '--raw', '--subdir', 'DAGS_FOLDER/soc_dag.py', '--cfg-path', '/tmp/tmpl88sa1v5']
[2024-06-01T03:18:16.884+0000] {standard_task_runner.py:91} INFO - Job 3673: Subtask domain_analysis
[2024-06-01T03:18:16.890+0000] {logging_mixin.py:188} WARNING - /home/***/.local/lib/python3.12/site-packages/***/settings.py:195 DeprecationWarning: The sql_alchemy_conn option in [core] has been moved to the sql_alchemy_conn option in [database] - the old setting has been used, but please update your config.
[2024-06-01T03:18:16.902+0000] {task_command.py:426} INFO - Running <TaskInstance: soc_domain_analysis.domain_analysis manual__2024-06-01T03:18:16.454131+00:00 [running]> on host a38c259dd974
[2024-06-01T03:18:16.931+0000] {taskinstance.py:2648} INFO - Exporting env vars: AIRFLOW_CTX_DAG_OWNER='***' AIRFLOW_CTX_DAG_ID='soc_domain_analysis' AIRFLOW_CTX_TASK_ID='domain_analysis' AIRFLOW_CTX_EXECUTION_DATE='2024-06-01T03:18:16.454131+00:00' AIRFLOW_CTX_TRY_NUMBER='1' AIRFLOW_CTX_DAG_RUN_ID='manual__2024-06-01T03:18:16.454131+00:00'
[2024-06-01T03:18:16.932+0000] {taskinstance.py:430} INFO - ::endgroup::
[2024-06-01T03:18:16.936+0000] {soc_dag.py:28} INFO - Starting to fetch soc
[2024-06-01T03:18:17.183+0000] {soc_dag.py:35} ERROR - Error fetching domains: Working outside of application context.

This typically means that you attempted to use functionality that needed
the current application. To solve this, set up an application context
with app.app_context(). See the documentation for more information.
[2024-06-01T03:18:17.183+0000] {taskinstance.py:441} INFO - ::group::Post task execution logs
[2024-06-01T03:18:17.184+0000] {taskinstance.py:2905} ERROR - Task failed with exception
Traceback (most recent call last):
  File "/home/airflow/.local/lib/python3.12/site-packages/airflow/models/taskinstance.py", line 465, in _execute_task
    result = _execute_callable(context=context, **execute_callable_kwargs)
             ^^^^^^^^^^^^^^^^^^^^^^^^^^^^^^^^^^^^^^^^^^^^^^^^^^^^^^^^^^^^^
  File "/home/airflow/.local/lib/python3.12/site-packages/airflow/models/taskinstance.py", line 432, in _execute_callable
    return execute_callable(context=context, **execute_callable_kwargs)
           ^^^^^^^^^^^^^^^^^^^^^^^^^^^^^^^^^^^^^^^^^^^^^^^^^^^^^^^^^^^^
  File "/home/airflow/.local/lib/python3.12/site-packages/airflow/models/baseoperator.py", line 400, in wrapper
    return func(self, *args, **kwargs)
           ^^^^^^^^^^^^^^^^^^^^^^^^^^^
  File "/home/airflow/.local/lib/python3.12/site-packages/airflow/operators/python.py", line 235, in execute
    return_value = self.execute_callable()
                   ^^^^^^^^^^^^^^^^^^^^^^^
  File "/home/airflow/.local/lib/python3.12/site-packages/airflow/operators/python.py", line 252, in execute_callable
    return self.python_callable(*self.op_args, **self.op_kwargs)
           ^^^^^^^^^^^^^^^^^^^^^^^^^^^^^^^^^^^^^^^^^^^^^^^^^^^^^
  File "/opt/airflow/dags/soc_dag.py", line 29, in domain_analysis
    result = DomainAnalysisOperator.query_domain("google.com")
             ^^^^^^^^^^^^^^^^^^^^^^^^^^^^^^^^^^^^^^^^^^^^^^^^^
  File "/opt/airflow/operators/analysis.py", line 171, in query_domain
    return jsonify(domain_info)
           ^^^^^^^^^^^^^^^^^^^^
  File "/home/airflow/.local/lib/python3.12/site-packages/flask/json/__init__.py", line 342, in jsonify
    return current_app.json.response(*args, **kwargs)
           ^^^^^^^^^^^^^^^^
  File "/home/airflow/.local/lib/python3.12/site-packages/werkzeug/local.py", line 316, in __get__
    obj = instance._get_current_object()
          ^^^^^^^^^^^^^^^^^^^^^^^^^^^^^^
  File "/home/airflow/.local/lib/python3.12/site-packages/werkzeug/local.py", line 513, in _get_current_object
    raise RuntimeError(unbound_message) from None
RuntimeError: Working outside of application context.

This typically means that you attempted to use functionality that needed
the current application. To solve this, set up an application context
with app.app_context(). See the documentation for more information.
[2024-06-01T03:18:17.195+0000] {taskinstance.py:1206} INFO - Marking task as UP_FOR_RETRY. dag_id=soc_domain_analysis, task_id=domain_analysis, run_id=manual__2024-06-01T03:18:16.454131+00:00, execution_date=20240601T031816, start_date=20240601T031816, end_date=20240601T031817
[2024-06-01T03:18:17.202+0000] {standard_task_runner.py:110} ERROR - Failed to execute job 3673 for task domain_analysis (Working outside of application context.

This typically means that you attempted to use functionality that needed
the current application. To solve this, set up an application context
with app.app_context(). See the documentation for more information.; 431)
[2024-06-01T03:18:17.243+0000] {local_task_job_runner.py:240} INFO - Task exited with return code 1
[2024-06-01T03:18:17.255+0000] {taskinstance.py:3498} INFO - 0 downstream tasks scheduled from follow-on schedule check
[2024-06-01T03:18:17.256+0000] {local_task_job_runner.py:222} INFO - ::endgroup::
