[2024-05-20T11:20:13.588+0000] {local_task_job_runner.py:120} INFO - ::group::Pre task execution logs
[2024-05-20T11:20:13.601+0000] {taskinstance.py:2076} INFO - Dependencies all met for dep_context=non-requeueable deps ti=<TaskInstance: domain_analysis_log.fetch_domains manual__2024-05-20T11:15:10.439076+00:00 [queued]>
[2024-05-20T11:20:13.604+0000] {taskinstance.py:2076} INFO - Dependencies all met for dep_context=requeueable deps ti=<TaskInstance: domain_analysis_log.fetch_domains manual__2024-05-20T11:15:10.439076+00:00 [queued]>
[2024-05-20T11:20:13.604+0000] {taskinstance.py:2306} INFO - Starting attempt 1 of 2
[2024-05-20T11:20:13.608+0000] {taskinstance.py:2330} INFO - Executing <Task(PythonOperator): fetch_domains> on 2024-05-20 11:15:10.439076+00:00
[2024-05-20T11:20:13.611+0000] {logging_mixin.py:188} WARNING - /home/***/.local/lib/python3.12/site-packages/***/task/task_runner/standard_task_runner.py:61 DeprecationWarning: This process (pid=390) is multi-threaded, use of fork() may lead to deadlocks in the child.
[2024-05-20T11:20:13.612+0000] {standard_task_runner.py:63} INFO - Started process 391 to run task
[2024-05-20T11:20:13.611+0000] {standard_task_runner.py:90} INFO - Running: ['***', 'tasks', 'run', 'domain_analysis_log', 'fetch_domains', 'manual__2024-05-20T11:15:10.439076+00:00', '--job-id', '479', '--raw', '--subdir', 'DAGS_FOLDER/analysis_dag.py', '--cfg-path', '/tmp/tmpzxsjaevg']
[2024-05-20T11:20:13.612+0000] {standard_task_runner.py:91} INFO - Job 479: Subtask fetch_domains
[2024-05-20T11:20:13.619+0000] {logging_mixin.py:188} WARNING - /home/***/.local/lib/python3.12/site-packages/***/settings.py:195 DeprecationWarning: The sql_alchemy_conn option in [core] has been moved to the sql_alchemy_conn option in [database] - the old setting has been used, but please update your config.
[2024-05-20T11:20:13.633+0000] {task_command.py:426} INFO - Running <TaskInstance: domain_analysis_log.fetch_domains manual__2024-05-20T11:15:10.439076+00:00 [running]> on host e2da04bc3f43
[2024-05-20T11:20:13.665+0000] {taskinstance.py:2648} INFO - Exporting env vars: AIRFLOW_CTX_DAG_OWNER='***' AIRFLOW_CTX_DAG_ID='domain_analysis_log' AIRFLOW_CTX_TASK_ID='fetch_domains' AIRFLOW_CTX_EXECUTION_DATE='2024-05-20T11:15:10.439076+00:00' AIRFLOW_CTX_TRY_NUMBER='1' AIRFLOW_CTX_DAG_RUN_ID='manual__2024-05-20T11:15:10.439076+00:00'
[2024-05-20T11:20:13.666+0000] {taskinstance.py:430} INFO - ::endgroup::
[2024-05-20T11:20:13.670+0000] {analysis_dag.py:28} INFO - Starting to fetch domains
[2024-05-20T11:20:13.674+0000] {base.py:84} INFO - Using connection ID '***_db' for task execution.
[2024-05-20T11:20:13.675+0000] {taskinstance.py:441} INFO - ::group::Post task execution logs
[2024-05-20T11:20:13.675+0000] {taskinstance.py:2905} ERROR - Task failed with exception
Traceback (most recent call last):
  File "/home/airflow/.local/lib/python3.12/site-packages/airflow/models/taskinstance.py", line 465, in _execute_task
    result = _execute_callable(context=context, **execute_callable_kwargs)
             ^^^^^^^^^^^^^^^^^^^^^^^^^^^^^^^^^^^^^^^^^^^^^^^^^^^^^^^^^^^^^
  File "/home/airflow/.local/lib/python3.12/site-packages/airflow/models/taskinstance.py", line 432, in _execute_callable
    return execute_callable(context=context, **execute_callable_kwargs)
           ^^^^^^^^^^^^^^^^^^^^^^^^^^^^^^^^^^^^^^^^^^^^^^^^^^^^^^^^^^^^
  File "/home/airflow/.local/lib/python3.12/site-packages/airflow/models/baseoperator.py", line 400, in wrapper
    return func(self, *args, **kwargs)
           ^^^^^^^^^^^^^^^^^^^^^^^^^^^
  File "/home/airflow/.local/lib/python3.12/site-packages/airflow/operators/python.py", line 235, in execute
    return_value = self.execute_callable()
                   ^^^^^^^^^^^^^^^^^^^^^^^
  File "/home/airflow/.local/lib/python3.12/site-packages/airflow/operators/python.py", line 252, in execute_callable
    return self.python_callable(*self.op_args, **self.op_kwargs)
           ^^^^^^^^^^^^^^^^^^^^^^^^^^^^^^^^^^^^^^^^^^^^^^^^^^^^^
  File "/opt/airflow/dags/analysis_dag.py", line 30, in fetch_domains
    conn = pg_hook.get_conn()
           ^^^^^^^^^^^^^^^^^^
  File "/home/airflow/.local/lib/python3.12/site-packages/airflow/providers/postgres/hooks/postgres.py", line 161, in get_conn
    self.conn = psycopg2.connect(**conn_args)
                ^^^^^^^^^^^^^^^^^^^^^^^^^^^^^
  File "/home/airflow/.local/lib/python3.12/site-packages/psycopg2/__init__.py", line 122, in connect
    conn = _connect(dsn, connection_factory=connection_factory, **kwasync)
           ^^^^^^^^^^^^^^^^^^^^^^^^^^^^^^^^^^^^^^^^^^^^^^^^^^^^^^^^^^^^^^^
psycopg2.OperationalError: connection to server at "localhost" (::1), port 5432 failed: Connection refused
	Is the server running on that host and accepting TCP/IP connections?
connection to server at "localhost" (127.0.0.1), port 5432 failed: Connection refused
	Is the server running on that host and accepting TCP/IP connections?

[2024-05-20T11:20:13.679+0000] {taskinstance.py:1206} INFO - Marking task as UP_FOR_RETRY. dag_id=domain_analysis_log, task_id=fetch_domains, run_id=manual__2024-05-20T11:15:10.439076+00:00, execution_date=20240520T111510, start_date=20240520T112013, end_date=20240520T112013
[2024-05-20T11:20:13.683+0000] {standard_task_runner.py:110} ERROR - Failed to execute job 479 for task fetch_domains (connection to server at "localhost" (::1), port 5432 failed: Connection refused
	Is the server running on that host and accepting TCP/IP connections?
connection to server at "localhost" (127.0.0.1), port 5432 failed: Connection refused
	Is the server running on that host and accepting TCP/IP connections?
; 391)
[2024-05-20T11:20:13.718+0000] {local_task_job_runner.py:240} INFO - Task exited with return code 1
[2024-05-20T11:20:13.726+0000] {taskinstance.py:3498} INFO - 0 downstream tasks scheduled from follow-on schedule check
[2024-05-20T11:20:13.727+0000] {local_task_job_runner.py:222} INFO - ::endgroup::
