[2024-06-01T03:00:24.115+0000] {task_context_logger.py:104} ERROR - Executor reports task instance <TaskInstance: soc_domain_analysis.domain_analysis manual__2024-06-01T03:00:22.369935+00:00 [queued]> finished (failed) although the task says it's queued. (Info: None) Was the task killed externally?
