[2024-05-20T12:38:02.866+0000] {local_task_job_runner.py:120} INFO - ::group::Pre task execution logs
[2024-05-20T12:38:02.879+0000] {taskinstance.py:2076} INFO - Dependencies all met for dep_context=non-requeueable deps ti=<TaskInstance: domain_analysis_full.fetch_and_analyze_domains scheduled__2023-01-18T06:00:00+00:00 [queued]>
[2024-05-20T12:38:02.882+0000] {taskinstance.py:2076} INFO - Dependencies all met for dep_context=requeueable deps ti=<TaskInstance: domain_analysis_full.fetch_and_analyze_domains scheduled__2023-01-18T06:00:00+00:00 [queued]>
[2024-05-20T12:38:02.882+0000] {taskinstance.py:2306} INFO - Starting attempt 1 of 2
[2024-05-20T12:38:02.887+0000] {taskinstance.py:2330} INFO - Executing <Task(PythonOperator): fetch_and_analyze_domains> on 2023-01-18 06:00:00+00:00
[2024-05-20T12:38:02.890+0000] {logging_mixin.py:188} WARNING - /home/***/.local/lib/python3.12/site-packages/***/task/task_runner/standard_task_runner.py:61 DeprecationWarning: This process (pid=1434) is multi-threaded, use of fork() may lead to deadlocks in the child.
[2024-05-20T12:38:02.890+0000] {standard_task_runner.py:63} INFO - Started process 1435 to run task
[2024-05-20T12:38:02.890+0000] {standard_task_runner.py:90} INFO - Running: ['***', 'tasks', 'run', 'domain_analysis_full', 'fetch_and_analyze_domains', 'scheduled__2023-01-18T06:00:00+00:00', '--job-id', '1930', '--raw', '--subdir', 'DAGS_FOLDER/analysis_test_dag.py', '--cfg-path', '/tmp/tmp53t3wd2b']
[2024-05-20T12:38:02.891+0000] {standard_task_runner.py:91} INFO - Job 1930: Subtask fetch_and_analyze_domains
[2024-05-20T12:38:02.898+0000] {logging_mixin.py:188} WARNING - /home/***/.local/lib/python3.12/site-packages/***/settings.py:195 DeprecationWarning: The sql_alchemy_conn option in [core] has been moved to the sql_alchemy_conn option in [database] - the old setting has been used, but please update your config.
[2024-05-20T12:38:02.912+0000] {task_command.py:426} INFO - Running <TaskInstance: domain_analysis_full.fetch_and_analyze_domains scheduled__2023-01-18T06:00:00+00:00 [running]> on host 667df64f43b9
[2024-05-20T12:38:02.945+0000] {taskinstance.py:2648} INFO - Exporting env vars: AIRFLOW_CTX_DAG_OWNER='***' AIRFLOW_CTX_DAG_ID='domain_analysis_full' AIRFLOW_CTX_TASK_ID='fetch_and_analyze_domains' AIRFLOW_CTX_EXECUTION_DATE='2023-01-18T06:00:00+00:00' AIRFLOW_CTX_TRY_NUMBER='1' AIRFLOW_CTX_DAG_RUN_ID='scheduled__2023-01-18T06:00:00+00:00'
[2024-05-20T12:38:02.946+0000] {taskinstance.py:430} INFO - ::endgroup::
[2024-05-20T12:38:02.950+0000] {analysis_test_dag.py:39} INFO - Starting to fetch domains
[2024-05-20T12:38:02.952+0000] {analysis_test_dag.py:69} INFO - Inserted analysis into domain_analysis for domain google.com
[2024-05-20T12:38:02.953+0000] {analysis_test_dag.py:52} ERROR - Error fetching and analyzing domains: (psycopg2.ProgrammingError) can't adapt type 'Row'
[SQL: INSERT INTO analysis.url_analysis (id, domain_id, url, alive, dt_update) VALUES (%(id)s, %(domain_id)s, %(url)s, %(alive)s, %(dt_update)s)]
[parameters: {'id': UUID('498e5c15-0e07-474d-9de8-8319008e076d'), 'domain_id': UUID('bca7786b-284b-4ce4-9581-4d868c52e867'), 'url': ('bca7786b-284b-4ce4-9581-4d868c52e867', 'google.com'), 'alive': True, 'dt_update': datetime.datetime(2024, 5, 20, 12, 38, 2, 952796)}]
(Background on this error at: https://sqlalche.me/e/14/f405)
[2024-05-20T12:38:02.953+0000] {taskinstance.py:441} INFO - ::group::Post task execution logs
[2024-05-20T12:38:02.953+0000] {taskinstance.py:2905} ERROR - Task failed with exception
Traceback (most recent call last):
  File "/home/airflow/.local/lib/python3.12/site-packages/sqlalchemy/engine/base.py", line 1910, in _execute_context
    self.dialect.do_execute(
  File "/home/airflow/.local/lib/python3.12/site-packages/sqlalchemy/engine/default.py", line 736, in do_execute
    cursor.execute(statement, parameters)
psycopg2.ProgrammingError: can't adapt type 'Row'

The above exception was the direct cause of the following exception:

Traceback (most recent call last):
  File "/home/airflow/.local/lib/python3.12/site-packages/airflow/models/taskinstance.py", line 465, in _execute_task
    result = _execute_callable(context=context, **execute_callable_kwargs)
             ^^^^^^^^^^^^^^^^^^^^^^^^^^^^^^^^^^^^^^^^^^^^^^^^^^^^^^^^^^^^^
  File "/home/airflow/.local/lib/python3.12/site-packages/airflow/models/taskinstance.py", line 432, in _execute_callable
    return execute_callable(context=context, **execute_callable_kwargs)
           ^^^^^^^^^^^^^^^^^^^^^^^^^^^^^^^^^^^^^^^^^^^^^^^^^^^^^^^^^^^^
  File "/home/airflow/.local/lib/python3.12/site-packages/airflow/models/baseoperator.py", line 400, in wrapper
    return func(self, *args, **kwargs)
           ^^^^^^^^^^^^^^^^^^^^^^^^^^^
  File "/home/airflow/.local/lib/python3.12/site-packages/airflow/operators/python.py", line 235, in execute
    return_value = self.execute_callable()
                   ^^^^^^^^^^^^^^^^^^^^^^^
  File "/home/airflow/.local/lib/python3.12/site-packages/airflow/operators/python.py", line 252, in execute_callable
    return self.python_callable(*self.op_args, **self.op_kwargs)
           ^^^^^^^^^^^^^^^^^^^^^^^^^^^^^^^^^^^^^^^^^^^^^^^^^^^^^
  File "/opt/airflow/dags/analysis_test_dag.py", line 46, in fetch_and_analyze_domains
    analyze_domain(session, domain)
  File "/opt/airflow/dags/analysis_test_dag.py", line 73, in analyze_domain
    session.execute(url_analysis.insert().values(
  File "/home/airflow/.local/lib/python3.12/site-packages/sqlalchemy/orm/session.py", line 1717, in execute
    result = conn._execute_20(statement, params or {}, execution_options)
             ^^^^^^^^^^^^^^^^^^^^^^^^^^^^^^^^^^^^^^^^^^^^^^^^^^^^^^^^^^^^
  File "/home/airflow/.local/lib/python3.12/site-packages/sqlalchemy/engine/base.py", line 1710, in _execute_20
    return meth(self, args_10style, kwargs_10style, execution_options)
           ^^^^^^^^^^^^^^^^^^^^^^^^^^^^^^^^^^^^^^^^^^^^^^^^^^^^^^^^^^^
  File "/home/airflow/.local/lib/python3.12/site-packages/sqlalchemy/sql/elements.py", line 334, in _execute_on_connection
    return connection._execute_clauseelement(
           ^^^^^^^^^^^^^^^^^^^^^^^^^^^^^^^^^^
  File "/home/airflow/.local/lib/python3.12/site-packages/sqlalchemy/engine/base.py", line 1577, in _execute_clauseelement
    ret = self._execute_context(
          ^^^^^^^^^^^^^^^^^^^^^^
  File "/home/airflow/.local/lib/python3.12/site-packages/sqlalchemy/engine/base.py", line 1953, in _execute_context
    self._handle_dbapi_exception(
  File "/home/airflow/.local/lib/python3.12/site-packages/sqlalchemy/engine/base.py", line 2134, in _handle_dbapi_exception
    util.raise_(
  File "/home/airflow/.local/lib/python3.12/site-packages/sqlalchemy/util/compat.py", line 211, in raise_
    raise exception
  File "/home/airflow/.local/lib/python3.12/site-packages/sqlalchemy/engine/base.py", line 1910, in _execute_context
    self.dialect.do_execute(
  File "/home/airflow/.local/lib/python3.12/site-packages/sqlalchemy/engine/default.py", line 736, in do_execute
    cursor.execute(statement, parameters)
sqlalchemy.exc.ProgrammingError: (psycopg2.ProgrammingError) can't adapt type 'Row'
[SQL: INSERT INTO analysis.url_analysis (id, domain_id, url, alive, dt_update) VALUES (%(id)s, %(domain_id)s, %(url)s, %(alive)s, %(dt_update)s)]
[parameters: {'id': UUID('498e5c15-0e07-474d-9de8-8319008e076d'), 'domain_id': UUID('bca7786b-284b-4ce4-9581-4d868c52e867'), 'url': ('bca7786b-284b-4ce4-9581-4d868c52e867', 'google.com'), 'alive': True, 'dt_update': datetime.datetime(2024, 5, 20, 12, 38, 2, 952796)}]
(Background on this error at: https://sqlalche.me/e/14/f405)
[2024-05-20T12:38:02.960+0000] {taskinstance.py:1206} INFO - Marking task as UP_FOR_RETRY. dag_id=domain_analysis_full, task_id=fetch_and_analyze_domains, run_id=scheduled__2023-01-18T06:00:00+00:00, execution_date=20230118T060000, start_date=20240520T123802, end_date=20240520T123802
[2024-05-20T12:38:02.964+0000] {standard_task_runner.py:110} ERROR - Failed to execute job 1930 for task fetch_and_analyze_domains ((psycopg2.ProgrammingError) can't adapt type 'Row'
[SQL: INSERT INTO analysis.url_analysis (id, domain_id, url, alive, dt_update) VALUES (%(id)s, %(domain_id)s, %(url)s, %(alive)s, %(dt_update)s)]
[parameters: {'id': UUID('498e5c15-0e07-474d-9de8-8319008e076d'), 'domain_id': UUID('bca7786b-284b-4ce4-9581-4d868c52e867'), 'url': ('bca7786b-284b-4ce4-9581-4d868c52e867', 'google.com'), 'alive': True, 'dt_update': datetime.datetime(2024, 5, 20, 12, 38, 2, 952796)}]
(Background on this error at: https://sqlalche.me/e/14/f405); 1435)
[2024-05-20T12:38:02.993+0000] {local_task_job_runner.py:240} INFO - Task exited with return code 1
[2024-05-20T12:38:03.001+0000] {taskinstance.py:3498} INFO - 0 downstream tasks scheduled from follow-on schedule check
[2024-05-20T12:38:03.001+0000] {local_task_job_runner.py:222} INFO - ::endgroup::
