[2024-05-19T00:23:19.726+0000] {local_task_job_runner.py:120} INFO - ::group::Pre task execution logs
[2024-05-19T00:23:19.744+0000] {taskinstance.py:2076} INFO - Dependencies all met for dep_context=non-requeueable deps ti=<TaskInstance: domain_url_analysis.fetch_domains scheduled__2023-01-01T00:00:00+00:00 [queued]>
[2024-05-19T00:23:19.748+0000] {taskinstance.py:2076} INFO - Dependencies all met for dep_context=requeueable deps ti=<TaskInstance: domain_url_analysis.fetch_domains scheduled__2023-01-01T00:00:00+00:00 [queued]>
[2024-05-19T00:23:19.748+0000] {taskinstance.py:2306} INFO - Starting attempt 1 of 2
[2024-05-19T00:23:19.755+0000] {taskinstance.py:2330} INFO - Executing <Task(PythonOperator): fetch_domains> on 2023-01-01 00:00:00+00:00
[2024-05-19T00:23:19.760+0000] {logging_mixin.py:188} WARNING - /home/***/.local/lib/python3.12/site-packages/***/task/task_runner/standard_task_runner.py:61 DeprecationWarning: This process (pid=254) is multi-threaded, use of fork() may lead to deadlocks in the child.
[2024-05-19T00:23:19.761+0000] {standard_task_runner.py:63} INFO - Started process 258 to run task
[2024-05-19T00:23:19.760+0000] {standard_task_runner.py:90} INFO - Running: ['***', 'tasks', 'run', 'domain_url_analysis', 'fetch_domains', 'scheduled__2023-01-01T00:00:00+00:00', '--job-id', '38', '--raw', '--subdir', 'DAGS_FOLDER/analysis_dag.py', '--cfg-path', '/tmp/tmpobtu270q']
[2024-05-19T00:23:19.762+0000] {standard_task_runner.py:91} INFO - Job 38: Subtask fetch_domains
[2024-05-19T00:23:19.772+0000] {logging_mixin.py:188} WARNING - /home/***/.local/lib/python3.12/site-packages/***/settings.py:195 DeprecationWarning: The sql_alchemy_conn option in [core] has been moved to the sql_alchemy_conn option in [database] - the old setting has been used, but please update your config.
[2024-05-19T00:23:19.797+0000] {task_command.py:426} INFO - Running <TaskInstance: domain_url_analysis.fetch_domains scheduled__2023-01-01T00:00:00+00:00 [running]> on host 99ec2e50f1b5
[2024-05-19T00:23:19.849+0000] {taskinstance.py:2648} INFO - Exporting env vars: AIRFLOW_CTX_DAG_OWNER='***' AIRFLOW_CTX_DAG_ID='domain_url_analysis' AIRFLOW_CTX_TASK_ID='fetch_domains' AIRFLOW_CTX_EXECUTION_DATE='2023-01-01T00:00:00+00:00' AIRFLOW_CTX_TRY_NUMBER='1' AIRFLOW_CTX_DAG_RUN_ID='scheduled__2023-01-01T00:00:00+00:00'
[2024-05-19T00:23:19.849+0000] {taskinstance.py:430} INFO - ::endgroup::
[2024-05-19T00:23:19.870+0000] {base.py:84} INFO - Using connection ID '***_db' for task execution.
[2024-05-19T00:23:19.927+0000] {taskinstance.py:441} INFO - ::group::Post task execution logs
[2024-05-19T00:23:19.928+0000] {taskinstance.py:2905} ERROR - Task failed with exception
Traceback (most recent call last):
  File "/home/airflow/.local/lib/python3.12/site-packages/airflow/models/taskinstance.py", line 465, in _execute_task
    result = _execute_callable(context=context, **execute_callable_kwargs)
             ^^^^^^^^^^^^^^^^^^^^^^^^^^^^^^^^^^^^^^^^^^^^^^^^^^^^^^^^^^^^^
  File "/home/airflow/.local/lib/python3.12/site-packages/airflow/models/taskinstance.py", line 432, in _execute_callable
    return execute_callable(context=context, **execute_callable_kwargs)
           ^^^^^^^^^^^^^^^^^^^^^^^^^^^^^^^^^^^^^^^^^^^^^^^^^^^^^^^^^^^^
  File "/home/airflow/.local/lib/python3.12/site-packages/airflow/models/baseoperator.py", line 400, in wrapper
    return func(self, *args, **kwargs)
           ^^^^^^^^^^^^^^^^^^^^^^^^^^^
  File "/home/airflow/.local/lib/python3.12/site-packages/airflow/operators/python.py", line 235, in execute
    return_value = self.execute_callable()
                   ^^^^^^^^^^^^^^^^^^^^^^^
  File "/home/airflow/.local/lib/python3.12/site-packages/airflow/operators/python.py", line 252, in execute_callable
    return self.python_callable(*self.op_args, **self.op_kwargs)
           ^^^^^^^^^^^^^^^^^^^^^^^^^^^^^^^^^^^^^^^^^^^^^^^^^^^^^
  File "/opt/airflow/dags/analysis_dag.py", line 29, in fetch_domains
    conn = pg_hook.get_conn()
           ^^^^^^^^^^^^^^^^^^
  File "/home/airflow/.local/lib/python3.12/site-packages/airflow/providers/postgres/hooks/postgres.py", line 161, in get_conn
    self.conn = psycopg2.connect(**conn_args)
                ^^^^^^^^^^^^^^^^^^^^^^^^^^^^^
  File "/home/airflow/.local/lib/python3.12/site-packages/psycopg2/__init__.py", line 122, in connect
    conn = _connect(dsn, connection_factory=connection_factory, **kwasync)
           ^^^^^^^^^^^^^^^^^^^^^^^^^^^^^^^^^^^^^^^^^^^^^^^^^^^^^^^^^^^^^^^
psycopg2.OperationalError: could not translate host name "mysql" to address: Name or service not known

[2024-05-19T00:23:19.941+0000] {taskinstance.py:1206} INFO - Marking task as UP_FOR_RETRY. dag_id=domain_url_analysis, task_id=fetch_domains, run_id=scheduled__2023-01-01T00:00:00+00:00, execution_date=20230101T000000, start_date=20240519T002319, end_date=20240519T002319
[2024-05-19T00:23:19.985+0000] {standard_task_runner.py:110} ERROR - Failed to execute job 38 for task fetch_domains (could not translate host name "mysql" to address: Name or service not known
; 258)
[2024-05-19T00:23:20.023+0000] {local_task_job_runner.py:240} INFO - Task exited with return code 1
[2024-05-19T00:23:20.032+0000] {local_task_job_runner.py:222} INFO - ::endgroup::
[2024-05-20T10:54:15.531+0000] {local_task_job_runner.py:120} INFO - ::group::Pre task execution logs
[2024-05-20T10:54:15.546+0000] {taskinstance.py:2076} INFO - Dependencies all met for dep_context=non-requeueable deps ti=<TaskInstance: domain_url_analysis.fetch_domains scheduled__2023-01-01T00:00:00+00:00 [queued]>
[2024-05-20T10:54:15.549+0000] {taskinstance.py:2076} INFO - Dependencies all met for dep_context=requeueable deps ti=<TaskInstance: domain_url_analysis.fetch_domains scheduled__2023-01-01T00:00:00+00:00 [queued]>
[2024-05-20T10:54:15.549+0000] {taskinstance.py:2306} INFO - Starting attempt 1 of 2
[2024-05-20T10:54:15.553+0000] {taskinstance.py:2330} INFO - Executing <Task(PythonOperator): fetch_domains> on 2023-01-01 00:00:00+00:00
[2024-05-20T10:54:15.557+0000] {logging_mixin.py:188} WARNING - /home/***/.local/lib/python3.12/site-packages/***/task/task_runner/standard_task_runner.py:61 DeprecationWarning: This process (pid=282) is multi-threaded, use of fork() may lead to deadlocks in the child.
[2024-05-20T10:54:15.557+0000] {standard_task_runner.py:63} INFO - Started process 283 to run task
[2024-05-20T10:54:15.556+0000] {standard_task_runner.py:90} INFO - Running: ['***', 'tasks', 'run', 'domain_url_analysis', 'fetch_domains', 'scheduled__2023-01-01T00:00:00+00:00', '--job-id', '469', '--raw', '--subdir', 'DAGS_FOLDER/analysis_dag.py', '--cfg-path', '/tmp/tmp3iby4sbk']
[2024-05-20T10:54:15.557+0000] {standard_task_runner.py:91} INFO - Job 469: Subtask fetch_domains
[2024-05-20T10:54:15.564+0000] {logging_mixin.py:188} WARNING - /home/***/.local/lib/python3.12/site-packages/***/settings.py:195 DeprecationWarning: The sql_alchemy_conn option in [core] has been moved to the sql_alchemy_conn option in [database] - the old setting has been used, but please update your config.
[2024-05-20T10:54:15.580+0000] {task_command.py:426} INFO - Running <TaskInstance: domain_url_analysis.fetch_domains scheduled__2023-01-01T00:00:00+00:00 [running]> on host e2da04bc3f43
[2024-05-20T10:54:15.613+0000] {taskinstance.py:2648} INFO - Exporting env vars: AIRFLOW_CTX_DAG_OWNER='***' AIRFLOW_CTX_DAG_ID='domain_url_analysis' AIRFLOW_CTX_TASK_ID='fetch_domains' AIRFLOW_CTX_EXECUTION_DATE='2023-01-01T00:00:00+00:00' AIRFLOW_CTX_TRY_NUMBER='1' AIRFLOW_CTX_DAG_RUN_ID='scheduled__2023-01-01T00:00:00+00:00'
[2024-05-20T10:54:15.613+0000] {taskinstance.py:430} INFO - ::endgroup::
[2024-05-20T10:54:15.631+0000] {base.py:84} INFO - Using connection ID '***_db' for task execution.
[2024-05-20T10:54:15.771+0000] {taskinstance.py:441} INFO - ::group::Post task execution logs
[2024-05-20T10:54:15.772+0000] {taskinstance.py:2905} ERROR - Task failed with exception
Traceback (most recent call last):
  File "/home/airflow/.local/lib/python3.12/site-packages/airflow/models/taskinstance.py", line 465, in _execute_task
    result = _execute_callable(context=context, **execute_callable_kwargs)
             ^^^^^^^^^^^^^^^^^^^^^^^^^^^^^^^^^^^^^^^^^^^^^^^^^^^^^^^^^^^^^
  File "/home/airflow/.local/lib/python3.12/site-packages/airflow/models/taskinstance.py", line 432, in _execute_callable
    return execute_callable(context=context, **execute_callable_kwargs)
           ^^^^^^^^^^^^^^^^^^^^^^^^^^^^^^^^^^^^^^^^^^^^^^^^^^^^^^^^^^^^
  File "/home/airflow/.local/lib/python3.12/site-packages/airflow/models/baseoperator.py", line 400, in wrapper
    return func(self, *args, **kwargs)
           ^^^^^^^^^^^^^^^^^^^^^^^^^^^
  File "/home/airflow/.local/lib/python3.12/site-packages/airflow/operators/python.py", line 235, in execute
    return_value = self.execute_callable()
                   ^^^^^^^^^^^^^^^^^^^^^^^
  File "/home/airflow/.local/lib/python3.12/site-packages/airflow/operators/python.py", line 252, in execute_callable
    return self.python_callable(*self.op_args, **self.op_kwargs)
           ^^^^^^^^^^^^^^^^^^^^^^^^^^^^^^^^^^^^^^^^^^^^^^^^^^^^^
  File "/opt/airflow/dags/analysis_dag.py", line 30, in fetch_domains
    conn = pg_hook.get_conn()
           ^^^^^^^^^^^^^^^^^^
  File "/home/airflow/.local/lib/python3.12/site-packages/airflow/providers/postgres/hooks/postgres.py", line 161, in get_conn
    self.conn = psycopg2.connect(**conn_args)
                ^^^^^^^^^^^^^^^^^^^^^^^^^^^^^
  File "/home/airflow/.local/lib/python3.12/site-packages/psycopg2/__init__.py", line 122, in connect
    conn = _connect(dsn, connection_factory=connection_factory, **kwasync)
           ^^^^^^^^^^^^^^^^^^^^^^^^^^^^^^^^^^^^^^^^^^^^^^^^^^^^^^^^^^^^^^^
psycopg2.OperationalError: could not translate host name "mysql" to address: Name or service not known

[2024-05-20T10:54:15.786+0000] {taskinstance.py:1206} INFO - Marking task as UP_FOR_RETRY. dag_id=domain_url_analysis, task_id=fetch_domains, run_id=scheduled__2023-01-01T00:00:00+00:00, execution_date=20230101T000000, start_date=20240520T105415, end_date=20240520T105415
[2024-05-20T10:54:15.793+0000] {standard_task_runner.py:110} ERROR - Failed to execute job 469 for task fetch_domains (could not translate host name "mysql" to address: Name or service not known
; 283)
[2024-05-20T10:54:15.832+0000] {local_task_job_runner.py:240} INFO - Task exited with return code 1
[2024-05-20T10:54:15.846+0000] {taskinstance.py:3498} INFO - 0 downstream tasks scheduled from follow-on schedule check
[2024-05-20T10:54:15.847+0000] {local_task_job_runner.py:222} INFO - ::endgroup::
