[2024-05-20T12:10:30.045+0000] {task_context_logger.py:104} ERROR - Executor reports task instance <TaskInstance: domain_analysis_single_insertion.fetch_and_analyze_domains scheduled__2023-01-10T08:00:00+00:00 [queued]> finished (failed) although the task says it's queued. (Info: None) Was the task killed externally?
