[2024-06-01T03:12:35.728+0000] {local_task_job_runner.py:120} INFO - ::group::Pre task execution logs
[2024-06-01T03:12:35.741+0000] {taskinstance.py:2076} INFO - Dependencies all met for dep_context=non-requeueable deps ti=<TaskInstance: soc_domain_analysis.domain_analysis manual__2024-06-01T03:12:35.037814+00:00 [queued]>
[2024-06-01T03:12:35.744+0000] {taskinstance.py:2076} INFO - Dependencies all met for dep_context=requeueable deps ti=<TaskInstance: soc_domain_analysis.domain_analysis manual__2024-06-01T03:12:35.037814+00:00 [queued]>
[2024-06-01T03:12:35.744+0000] {taskinstance.py:2306} INFO - Starting attempt 1 of 3
[2024-06-01T03:12:35.748+0000] {taskinstance.py:2330} INFO - Executing <Task(PythonOperator): domain_analysis> on 2024-06-01 03:12:35.037814+00:00
[2024-06-01T03:12:35.751+0000] {logging_mixin.py:188} WARNING - /home/***/.local/lib/python3.12/site-packages/***/task/task_runner/standard_task_runner.py:61 DeprecationWarning: This process (pid=257) is multi-threaded, use of fork() may lead to deadlocks in the child.
[2024-06-01T03:12:35.752+0000] {standard_task_runner.py:63} INFO - Started process 258 to run task
[2024-06-01T03:12:35.751+0000] {standard_task_runner.py:90} INFO - Running: ['***', 'tasks', 'run', 'soc_domain_analysis', 'domain_analysis', 'manual__2024-06-01T03:12:35.037814+00:00', '--job-id', '3669', '--raw', '--subdir', 'DAGS_FOLDER/soc_dag.py', '--cfg-path', '/tmp/tmpea11tj6s']
[2024-06-01T03:12:35.752+0000] {standard_task_runner.py:91} INFO - Job 3669: Subtask domain_analysis
[2024-06-01T03:12:35.759+0000] {logging_mixin.py:188} WARNING - /home/***/.local/lib/python3.12/site-packages/***/settings.py:195 DeprecationWarning: The sql_alchemy_conn option in [core] has been moved to the sql_alchemy_conn option in [database] - the old setting has been used, but please update your config.
[2024-06-01T03:12:35.774+0000] {task_command.py:426} INFO - Running <TaskInstance: soc_domain_analysis.domain_analysis manual__2024-06-01T03:12:35.037814+00:00 [running]> on host a38c259dd974
[2024-06-01T03:12:35.808+0000] {taskinstance.py:2648} INFO - Exporting env vars: AIRFLOW_CTX_DAG_OWNER='***' AIRFLOW_CTX_DAG_ID='soc_domain_analysis' AIRFLOW_CTX_TASK_ID='domain_analysis' AIRFLOW_CTX_EXECUTION_DATE='2024-06-01T03:12:35.037814+00:00' AIRFLOW_CTX_TRY_NUMBER='1' AIRFLOW_CTX_DAG_RUN_ID='manual__2024-06-01T03:12:35.037814+00:00'
[2024-06-01T03:12:35.808+0000] {taskinstance.py:430} INFO - ::endgroup::
[2024-06-01T03:12:35.819+0000] {soc_dag.py:28} INFO - Starting to fetch soc
[2024-06-01T03:12:35.819+0000] {soc_dag.py:35} ERROR - Error fetching domains: name 'WhoisException' is not defined
[2024-06-01T03:12:35.820+0000] {taskinstance.py:441} INFO - ::group::Post task execution logs
[2024-06-01T03:12:35.820+0000] {taskinstance.py:2905} ERROR - Task failed with exception
Traceback (most recent call last):
  File "/opt/airflow/operators/analysis.py", line 55, in get_domain_creation_date
    domain_info = whois.whois(domain)
                  ^^^^^^^^^^^
AttributeError: module 'whois' has no attribute 'whois'

During handling of the above exception, another exception occurred:

Traceback (most recent call last):
  File "/home/airflow/.local/lib/python3.12/site-packages/airflow/models/taskinstance.py", line 465, in _execute_task
    result = _execute_callable(context=context, **execute_callable_kwargs)
             ^^^^^^^^^^^^^^^^^^^^^^^^^^^^^^^^^^^^^^^^^^^^^^^^^^^^^^^^^^^^^
  File "/home/airflow/.local/lib/python3.12/site-packages/airflow/models/taskinstance.py", line 432, in _execute_callable
    return execute_callable(context=context, **execute_callable_kwargs)
           ^^^^^^^^^^^^^^^^^^^^^^^^^^^^^^^^^^^^^^^^^^^^^^^^^^^^^^^^^^^^
  File "/home/airflow/.local/lib/python3.12/site-packages/airflow/models/baseoperator.py", line 400, in wrapper
    return func(self, *args, **kwargs)
           ^^^^^^^^^^^^^^^^^^^^^^^^^^^
  File "/home/airflow/.local/lib/python3.12/site-packages/airflow/operators/python.py", line 235, in execute
    return_value = self.execute_callable()
                   ^^^^^^^^^^^^^^^^^^^^^^^
  File "/home/airflow/.local/lib/python3.12/site-packages/airflow/operators/python.py", line 252, in execute_callable
    return self.python_callable(*self.op_args, **self.op_kwargs)
           ^^^^^^^^^^^^^^^^^^^^^^^^^^^^^^^^^^^^^^^^^^^^^^^^^^^^^
  File "/opt/airflow/dags/soc_dag.py", line 29, in domain_analysis
    result = DomainAnalysisOperator.query_domain("google.com")
             ^^^^^^^^^^^^^^^^^^^^^^^^^^^^^^^^^^^^^^^^^^^^^^^^^
  File "/opt/airflow/operators/analysis.py", line 160, in query_domain
    domain_creation_date = DomainAnalysisOperator.get_domain_creation_date(domain)
                           ^^^^^^^^^^^^^^^^^^^^^^^^^^^^^^^^^^^^^^^^^^^^^^^^^^^^^^^
  File "/opt/airflow/operators/analysis.py", line 64, in get_domain_creation_date
    except WhoisException as e:
           ^^^^^^^^^^^^^^
NameError: name 'WhoisException' is not defined. Did you mean: 'BaseException'?
[2024-06-01T03:12:35.826+0000] {taskinstance.py:1206} INFO - Marking task as UP_FOR_RETRY. dag_id=soc_domain_analysis, task_id=domain_analysis, run_id=manual__2024-06-01T03:12:35.037814+00:00, execution_date=20240601T031235, start_date=20240601T031235, end_date=20240601T031235
[2024-06-01T03:12:35.830+0000] {standard_task_runner.py:110} ERROR - Failed to execute job 3669 for task domain_analysis (name 'WhoisException' is not defined; 258)
[2024-06-01T03:12:35.854+0000] {local_task_job_runner.py:240} INFO - Task exited with return code 1
[2024-06-01T03:12:35.860+0000] {taskinstance.py:3498} INFO - 0 downstream tasks scheduled from follow-on schedule check
[2024-06-01T03:12:35.861+0000] {local_task_job_runner.py:222} INFO - ::endgroup::
