[2024-05-20T08:19:46.343+0000] {local_task_job_runner.py:120} INFO - ::group::Pre task execution logs
[2024-05-20T08:19:46.356+0000] {taskinstance.py:2076} INFO - Dependencies all met for dep_context=non-requeueable deps ti=<TaskInstance: domain_url_analysis.fetch_domains scheduled__2023-01-18T01:00:00+00:00 [queued]>
[2024-05-20T08:19:46.359+0000] {taskinstance.py:2076} INFO - Dependencies all met for dep_context=requeueable deps ti=<TaskInstance: domain_url_analysis.fetch_domains scheduled__2023-01-18T01:00:00+00:00 [queued]>
[2024-05-20T08:19:46.359+0000] {taskinstance.py:2306} INFO - Starting attempt 1 of 2
[2024-05-20T08:19:46.363+0000] {taskinstance.py:2330} INFO - Executing <Task(PythonOperator): fetch_domains> on 2023-01-18 01:00:00+00:00
[2024-05-20T08:19:46.366+0000] {logging_mixin.py:188} WARNING - /home/***/.local/lib/python3.12/site-packages/***/task/task_runner/standard_task_runner.py:61 DeprecationWarning: This process (pid=5717) is multi-threaded, use of fork() may lead to deadlocks in the child.
[2024-05-20T08:19:46.366+0000] {standard_task_runner.py:63} INFO - Started process 5718 to run task
[2024-05-20T08:19:46.366+0000] {standard_task_runner.py:90} INFO - Running: ['***', 'tasks', 'run', 'domain_url_analysis', 'fetch_domains', 'scheduled__2023-01-18T01:00:00+00:00', '--job-id', '224', '--raw', '--subdir', 'DAGS_FOLDER/analysis_dag.py', '--cfg-path', '/tmp/tmp4cwnv7kf']
[2024-05-20T08:19:46.367+0000] {standard_task_runner.py:91} INFO - Job 224: Subtask fetch_domains
[2024-05-20T08:19:46.373+0000] {logging_mixin.py:188} WARNING - /home/***/.local/lib/python3.12/site-packages/***/settings.py:195 DeprecationWarning: The sql_alchemy_conn option in [core] has been moved to the sql_alchemy_conn option in [database] - the old setting has been used, but please update your config.
[2024-05-20T08:19:46.387+0000] {task_command.py:426} INFO - Running <TaskInstance: domain_url_analysis.fetch_domains scheduled__2023-01-18T01:00:00+00:00 [running]> on host 99ec2e50f1b5
[2024-05-20T08:19:46.418+0000] {taskinstance.py:2648} INFO - Exporting env vars: AIRFLOW_CTX_DAG_OWNER='***' AIRFLOW_CTX_DAG_ID='domain_url_analysis' AIRFLOW_CTX_TASK_ID='fetch_domains' AIRFLOW_CTX_EXECUTION_DATE='2023-01-18T01:00:00+00:00' AIRFLOW_CTX_TRY_NUMBER='1' AIRFLOW_CTX_DAG_RUN_ID='scheduled__2023-01-18T01:00:00+00:00'
[2024-05-20T08:19:46.419+0000] {taskinstance.py:430} INFO - ::endgroup::
[2024-05-20T08:19:46.426+0000] {base.py:84} INFO - Using connection ID '***_db' for task execution.
[2024-05-20T08:19:46.429+0000] {taskinstance.py:441} INFO - ::group::Post task execution logs
[2024-05-20T08:19:46.429+0000] {taskinstance.py:2905} ERROR - Task failed with exception
Traceback (most recent call last):
  File "/home/airflow/.local/lib/python3.12/site-packages/airflow/models/taskinstance.py", line 465, in _execute_task
    result = _execute_callable(context=context, **execute_callable_kwargs)
             ^^^^^^^^^^^^^^^^^^^^^^^^^^^^^^^^^^^^^^^^^^^^^^^^^^^^^^^^^^^^^
  File "/home/airflow/.local/lib/python3.12/site-packages/airflow/models/taskinstance.py", line 432, in _execute_callable
    return execute_callable(context=context, **execute_callable_kwargs)
           ^^^^^^^^^^^^^^^^^^^^^^^^^^^^^^^^^^^^^^^^^^^^^^^^^^^^^^^^^^^^
  File "/home/airflow/.local/lib/python3.12/site-packages/airflow/models/baseoperator.py", line 400, in wrapper
    return func(self, *args, **kwargs)
           ^^^^^^^^^^^^^^^^^^^^^^^^^^^
  File "/home/airflow/.local/lib/python3.12/site-packages/airflow/operators/python.py", line 235, in execute
    return_value = self.execute_callable()
                   ^^^^^^^^^^^^^^^^^^^^^^^
  File "/home/airflow/.local/lib/python3.12/site-packages/airflow/operators/python.py", line 252, in execute_callable
    return self.python_callable(*self.op_args, **self.op_kwargs)
           ^^^^^^^^^^^^^^^^^^^^^^^^^^^^^^^^^^^^^^^^^^^^^^^^^^^^^
  File "/opt/airflow/dags/analysis_dag.py", line 32, in fetch_domains
    conn = pg_hook.get_conn()
           ^^^^^^^^^^^^^^^^^^
  File "/home/airflow/.local/lib/python3.12/site-packages/airflow/providers/postgres/hooks/postgres.py", line 161, in get_conn
    self.conn = psycopg2.connect(**conn_args)
                ^^^^^^^^^^^^^^^^^^^^^^^^^^^^^
  File "/home/airflow/.local/lib/python3.12/site-packages/psycopg2/__init__.py", line 122, in connect
    conn = _connect(dsn, connection_factory=connection_factory, **kwasync)
           ^^^^^^^^^^^^^^^^^^^^^^^^^^^^^^^^^^^^^^^^^^^^^^^^^^^^^^^^^^^^^^^
psycopg2.OperationalError: could not translate host name "mysql" to address: Name or service not known

[2024-05-20T08:19:46.434+0000] {taskinstance.py:1206} INFO - Marking task as UP_FOR_RETRY. dag_id=domain_url_analysis, task_id=fetch_domains, run_id=scheduled__2023-01-18T01:00:00+00:00, execution_date=20230118T010000, start_date=20240520T081946, end_date=20240520T081946
[2024-05-20T08:19:46.437+0000] {standard_task_runner.py:110} ERROR - Failed to execute job 224 for task fetch_domains (could not translate host name "mysql" to address: Name or service not known
; 5718)
[2024-05-20T08:19:46.466+0000] {local_task_job_runner.py:240} INFO - Task exited with return code 1
[2024-05-20T08:19:46.475+0000] {taskinstance.py:3498} INFO - 0 downstream tasks scheduled from follow-on schedule check
[2024-05-20T08:19:46.476+0000] {local_task_job_runner.py:222} INFO - ::endgroup::
