[2024-06-01T04:07:55.855+0000] {local_task_job_runner.py:120} INFO - ::group::Pre task execution logs
[2024-06-01T04:07:55.868+0000] {taskinstance.py:2076} INFO - Dependencies all met for dep_context=non-requeueable deps ti=<TaskInstance: soc_domain_analysis.domain_analysis manual__2024-06-01T04:07:55.447563+00:00 [queued]>
[2024-06-01T04:07:55.871+0000] {taskinstance.py:2076} INFO - Dependencies all met for dep_context=requeueable deps ti=<TaskInstance: soc_domain_analysis.domain_analysis manual__2024-06-01T04:07:55.447563+00:00 [queued]>
[2024-06-01T04:07:55.872+0000] {taskinstance.py:2306} INFO - Starting attempt 1 of 3
[2024-06-01T04:07:55.877+0000] {taskinstance.py:2330} INFO - Executing <Task(PythonOperator): domain_analysis> on 2024-06-01 04:07:55.447563+00:00
[2024-06-01T04:07:55.879+0000] {logging_mixin.py:188} WARNING - /home/***/.local/lib/python3.12/site-packages/***/task/task_runner/standard_task_runner.py:61 DeprecationWarning: This process (pid=1541) is multi-threaded, use of fork() may lead to deadlocks in the child.
[2024-06-01T04:07:55.880+0000] {standard_task_runner.py:63} INFO - Started process 1542 to run task
[2024-06-01T04:07:55.879+0000] {standard_task_runner.py:90} INFO - Running: ['***', 'tasks', 'run', 'soc_domain_analysis', 'domain_analysis', 'manual__2024-06-01T04:07:55.447563+00:00', '--job-id', '3677', '--raw', '--subdir', 'DAGS_FOLDER/soc_dag.py', '--cfg-path', '/tmp/tmpohporiq7']
[2024-06-01T04:07:55.881+0000] {standard_task_runner.py:91} INFO - Job 3677: Subtask domain_analysis
[2024-06-01T04:07:55.888+0000] {logging_mixin.py:188} WARNING - /home/***/.local/lib/python3.12/site-packages/***/settings.py:195 DeprecationWarning: The sql_alchemy_conn option in [core] has been moved to the sql_alchemy_conn option in [database] - the old setting has been used, but please update your config.
[2024-06-01T04:07:55.902+0000] {task_command.py:426} INFO - Running <TaskInstance: soc_domain_analysis.domain_analysis manual__2024-06-01T04:07:55.447563+00:00 [running]> on host e11ec26ff801
[2024-06-01T04:07:55.936+0000] {taskinstance.py:2648} INFO - Exporting env vars: AIRFLOW_CTX_DAG_OWNER='***' AIRFLOW_CTX_DAG_ID='soc_domain_analysis' AIRFLOW_CTX_TASK_ID='domain_analysis' AIRFLOW_CTX_EXECUTION_DATE='2024-06-01T04:07:55.447563+00:00' AIRFLOW_CTX_TRY_NUMBER='1' AIRFLOW_CTX_DAG_RUN_ID='manual__2024-06-01T04:07:55.447563+00:00'
[2024-06-01T04:07:55.937+0000] {taskinstance.py:430} INFO - ::endgroup::
[2024-06-01T04:07:55.942+0000] {soc_dag.py:28} INFO - Starting to fetch soc
[2024-06-01T04:07:56.130+0000] {soc_dag.py:35} ERROR - Error fetching domains: 'dict' object has no attribute 'mx'
[2024-06-01T04:07:56.131+0000] {taskinstance.py:441} INFO - ::group::Post task execution logs
[2024-06-01T04:07:56.132+0000] {taskinstance.py:2905} ERROR - Task failed with exception
Traceback (most recent call last):
  File "/home/airflow/.local/lib/python3.12/site-packages/airflow/models/taskinstance.py", line 465, in _execute_task
    result = _execute_callable(context=context, **execute_callable_kwargs)
             ^^^^^^^^^^^^^^^^^^^^^^^^^^^^^^^^^^^^^^^^^^^^^^^^^^^^^^^^^^^^^
  File "/home/airflow/.local/lib/python3.12/site-packages/airflow/models/taskinstance.py", line 432, in _execute_callable
    return execute_callable(context=context, **execute_callable_kwargs)
           ^^^^^^^^^^^^^^^^^^^^^^^^^^^^^^^^^^^^^^^^^^^^^^^^^^^^^^^^^^^^
  File "/home/airflow/.local/lib/python3.12/site-packages/airflow/models/baseoperator.py", line 400, in wrapper
    return func(self, *args, **kwargs)
           ^^^^^^^^^^^^^^^^^^^^^^^^^^^
  File "/home/airflow/.local/lib/python3.12/site-packages/airflow/operators/python.py", line 235, in execute
    return_value = self.execute_callable()
                   ^^^^^^^^^^^^^^^^^^^^^^^
  File "/home/airflow/.local/lib/python3.12/site-packages/airflow/operators/python.py", line 252, in execute_callable
    return self.python_callable(*self.op_args, **self.op_kwargs)
           ^^^^^^^^^^^^^^^^^^^^^^^^^^^^^^^^^^^^^^^^^^^^^^^^^^^^^
  File "/opt/airflow/dags/soc_dag.py", line 30, in domain_analysis
    logging.info("RESULT ------>" + result.mx)
                                    ^^^^^^^^^
AttributeError: 'dict' object has no attribute 'mx'
[2024-06-01T04:07:56.144+0000] {taskinstance.py:1206} INFO - Marking task as UP_FOR_RETRY. dag_id=soc_domain_analysis, task_id=domain_analysis, run_id=manual__2024-06-01T04:07:55.447563+00:00, execution_date=20240601T040755, start_date=20240601T040755, end_date=20240601T040756
[2024-06-01T04:07:56.152+0000] {standard_task_runner.py:110} ERROR - Failed to execute job 3677 for task domain_analysis ('dict' object has no attribute 'mx'; 1542)
[2024-06-01T04:07:56.167+0000] {local_task_job_runner.py:240} INFO - Task exited with return code 1
[2024-06-01T04:07:56.178+0000] {taskinstance.py:3498} INFO - 0 downstream tasks scheduled from follow-on schedule check
[2024-06-01T04:07:56.179+0000] {local_task_job_runner.py:222} INFO - ::endgroup::
