[2024-05-20T12:49:07.694+0000] {task_context_logger.py:104} ERROR - Executor reports task instance <TaskInstance: domain_analysis.analyze_domains scheduled__2023-01-03T09:00:00+00:00 [queued]> finished (failed) although the task says it's queued. (Info: None) Was the task killed externally?
